export const handleErrorAsync = (func) => {
  return async (req, res, next) => {
    try {
      await func(req, res, next);
    } catch (error) {
      next(error);
    }
  };
};
